Workbook

Sheet _CHART_HELPER

Sheet LIVE
A1: LIVE
A2: ID | B2: DATE | C2: DAY | D2: TIME | E2: PL | F2: SPORT | G2: CTRY | H2: TOURNAMENT | I2: HOME | J2: AWAY | K2: 1SC | L2: 2SC | M2: _Type | N2: _Platform | O2: _SportName
A3: =IF(SET!P1="","",SET!L1) | B3: =IF(SET!P1="","",TEXT(DATE(SET!O1,SET!N1,SET!M1),"DD/MM/YYYY")) | C3: =IF(SET!P1="","",SET!P1) | D3: =IF(SET!P1="","",TEXT(TIME(SET!Q1,SET!R1,0),"HH:MM")) | E3: =IF(SET!P1="","",IF(SET!T1="iScout","📱",IF(SET!T1="XSA Neo","💻","📞"))) | F3: =IF(SET!P1="","",IFERROR(VLOOKUP(SET!U1,SET!$E$118:$G$161,2,FALSE),"⚽")) | G3: =IF(SET!P1="","",IFERROR(VLOOKUP(SET!V1,SET!$B$56:$C$270,2,FALSE),"🌍")) | H3: =IF(SET!P1="","",SET!W1) | I3: =IF(SET!P1="","",SET!X1) | J3: =IF(SET!P1="","",SET!Y1) | K3: =IF(SET!P1="","",SUBSTITUTE(SET!AA1,"(Stream)","")) | L3: =IF(SET!P1="","",SUBSTITUTE(SET!AC1,"(Stream)","")) | M3: =IF(SET!P1="","",SET!T1) | N3: =IF(SET!P1="","",SET!S1) | O3: =IF(SET!P1="","",SET!U1)
A4: =IF(SET!P2="","",SET!L2) | B4: =IF(SET!P2="","",TEXT(DATE(SET!O2,SET!N2,SET!M2),"DD/MM/YYYY")) | C4: =IF(SET!P2="","",SET!P2) | D4: =IF(SET!P2="","",TEXT(TIME(SET!Q2,SET!R2,0),"HH:MM")) | E4: =IF(SET!P2="","",IF(SET!T2="iScout","📱",IF(SET!T2="XSA Neo","💻","📞"))) | F4: =IF(SET!P2="","",IFERROR(VLOOKUP(SET!U2,SET!$E$118:$G$161,2,FALSE),"⚽")) | G4: =IF(SET!P2="","",IFERROR(VLOOKUP(SET!V2,SET!$B$56:$C$270,2,FALSE),"🌍")) | H4: =IF(SET!P2="","",SET!W2) | I4: =IF(SET!P2="","",SET!X2) | J4: =IF(SET!P2="","",SET!Y2) | K4: =IF(SET!P2="","",SUBSTITUTE(SET!AA2,"(Stream)","")) | L4: =IF(SET!P2="","",SUBSTITUTE(SET!AC2,"(Stream)","")) | M4: =IF(SET!P2="","",SET!T2) | N4: =IF(SET!P2="","",SET!S2) | O4: =IF(SET!P2="","",SET!U2)
A5: =IF(SET!P3="","",SET!L3) | B5: =IF(SET!P3="","",TEXT(DATE(SET!O3,SET!N3,SET!M3),"DD/MM/YYYY")) | C5: =IF(SET!P3="","",SET!P3) | D5: =IF(SET!P3="","",TEXT(TIME(SET!Q3,SET!R3,0),"HH:MM")) | E5: =IF(SET!P3="","",IF(SET!T3="iScout","📱",IF(SET!T3="XSA Neo","💻","📞"))) | F5: =IF(SET!P3="","",IFERROR(VLOOKUP(SET!U3,SET!$E$118:$G$161,2,FALSE),"⚽")) | G5: =IF(SET!P3="","",IFERROR(VLOOKUP(SET!V3,SET!$B$56:$C$270,2,FALSE),"🌍")) | H5: =IF(SET!P3="","",SET!W3) | I5: =IF(SET!P3="","",SET!X3) | J5: =IF(SET!P3="","",SET!Y3) | K5: =IF(SET!P3="","",SUBSTITUTE(SET!AA3,"(Stream)","")) | L5: =IF(SET!P3="","",SUBSTITUTE(SET!AC3,"(Stream)","")) | M5: =IF(SET!P3="","",SET!T3) | N5: =IF(SET!P3="","",SET!S3) | O5: =IF(SET!P3="","",SET!U3)
A6: =IF(SET!P4="","",SET!L4) | B6: =IF(SET!P4="","",TEXT(DATE(SET!O4,SET!N4,SET!M4),"DD/MM/YYYY")) | C6: =IF(SET!P4="","",SET!P4) | D6: =IF(SET!P4="","",TEXT(TIME(SET!Q4,SET!R4,0),"HH:MM")) | E6: =IF(SET!P4="","",IF(SET!T4="iScout","📱",IF(SET!T4="XSA Neo","💻","📞"))) | F6: =IF(SET!P4="","",IFERROR(VLOOKUP(SET!U4,SET!$E$118:$G$161,2,FALSE),"⚽")) | G6: =IF(SET!P4="","",IFERROR(VLOOKUP(SET!V4,SET!$B$56:$C$270,2,FALSE),"🌍")) | H6: =IF(SET!P4="","",SET!W4) | I6: =IF(SET!P4="","",SET!X4) | J6: =IF(SET!P4="","",SET!Y4) | K6: =IF(SET!P4="","",SUBSTITUTE(SET!AA4,"(Stream)","")) | L6: =IF(SET!P4="","",SUBSTITUTE(SET!AC4,"(Stream)","")) | M6: =IF(SET!P4="","",SET!T4) | N6: =IF(SET!P4="","",SET!S4) | O6: =IF(SET!P4="","",SET!U4)
A7: =IF(SET!P5="","",SET!L5) | B7: =IF(SET!P5="","",TEXT(DATE(SET!O5,SET!N5,SET!M5),"DD/MM/YYYY")) | C7: =IF(SET!P5="","",SET!P5) | D7: =IF(SET!P5="","",TEXT(TIME(SET!Q5,SET!R5,0),"HH:MM")) | E7: =IF(SET!P5="","",IF(SET!T5="iScout","📱",IF(SET!T5="XSA Neo","💻","📞"))) | F7: =IF(SET!P5="","",IFERROR(VLOOKUP(SET!U5,SET!$E$118:$G$161,2,FALSE),"⚽")) | G7: =IF(SET!P5="","",IFERROR(VLOOKUP(SET!V5,SET!$B$56:$C$270,2,FALSE),"🌍")) | H7: =IF(SET!P5="","",SET!W5) | I7: =IF(SET!P5="","",SET!X5) | J7: =IF(SET!P5="","",SET!Y5) | K7: =IF(SET!P5="","",SUBSTITUTE(SET!AA5,"(Stream)","")) | L7: =IF(SET!P5="","",SUBSTITUTE(SET!AC5,"(Stream)","")) | M7: =IF(SET!P5="","",SET!T5) | N7: =IF(SET!P5="","",SET!S5) | O7: =IF(SET!P5="","",SET!U5)
A8: =IF(SET!P6="","",SET!L6) | B8: =IF(SET!P6="","",TEXT(DATE(SET!O6,SET!N6,SET!M6),"DD/MM/YYYY")) | C8: =IF(SET!P6="","",SET!P6) | D8: =IF(SET!P6="","",TEXT(TIME(SET!Q6,SET!R6,0),"HH:MM")) | E8: =IF(SET!P6="","",IF(SET!T6="iScout","📱",IF(SET!T6="XSA Neo","💻","📞"))) | F8: =IF(SET!P6="","",IFERROR(VLOOKUP(SET!U6,SET!$E$118:$G$161,2,FALSE),"⚽")) | G8: =IF(SET!P6="","",IFERROR(VLOOKUP(SET!V6,SET!$B$56:$C$270,2,FALSE),"🌍")) | H8: =IF(SET!P6="","",SET!W6) | I8: =IF(SET!P6="","",SET!X6) | J8: =IF(SET!P6="","",SET!Y6) | K8: =IF(SET!P6="","",SUBSTITUTE(SET!AA6,"(Stream)","")) | L8: =IF(SET!P6="","",SUBSTITUTE(SET!AC6,"(Stream)","")) | M8: =IF(SET!P6="","",SET!T6) | N8: =IF(SET!P6="","",SET!S6) | O8: =IF(SET!P6="","",SET!U6)
A9: =IF(SET!P7="","",SET!L7) | B9: =IF(SET!P7="","",TEXT(DATE(SET!O7,SET!N7,SET!M7),"DD/MM/YYYY")) | C9: =IF(SET!P7="","",SET!P7) | D9: =IF(SET!P7="","",TEXT(TIME(SET!Q7,SET!R7,0),"HH:MM")) | E9: =IF(SET!P7="","",IF(SET!T7="iScout","📱",IF(SET!T7="XSA Neo","💻","📞"))) | F9: =IF(SET!P7="","",IFERROR(VLOOKUP(SET!U7,SET!$E$118:$G$161,2,FALSE),"⚽")) | G9: =IF(SET!P7="","",IFERROR(VLOOKUP(SET!V7,SET!$B$56:$C$270,2,FALSE),"🌍")) | H9: =IF(SET!P7="","",SET!W7) | I9: =IF(SET!P7="","",SET!X7) | J9: =IF(SET!P7="","",SET!Y7) | K9: =IF(SET!P7="","",SUBSTITUTE(SET!AA7,"(Stream)","")) | L9: =IF(SET!P7="","",SUBSTITUTE(SET!AC7,"(Stream)","")) | M9: =IF(SET!P7="","",SET!T7) | N9: =IF(SET!P7="","",SET!S7) | O9: =IF(SET!P7="","",SET!U7)
A10: =IF(SET!P8="","",SET!L8) | B10: =IF(SET!P8="","",TEXT(DATE(SET!O8,SET!N8,SET!M8),"DD/MM/YYYY")) | C10: =IF(SET!P8="","",SET!P8) | D10: =IF(SET!P8="","",TEXT(TIME(SET!Q8,SET!R8,0),"HH:MM")) | E10: =IF(SET!P8="","",IF(SET!T8="iScout","📱",IF(SET!T8="XSA Neo","💻","📞"))) | F10: =IF(SET!P8="","",IFERROR(VLOOKUP(SET!U8,SET!$E$118:$G$161,2,FALSE),"⚽")) | G10: =IF(SET!P8="","",IFERROR(VLOOKUP(SET!V8,SET!$B$56:$C$270,2,FALSE),"🌍")) | H10: =IF(SET!P8="","",SET!W8) | I10: =IF(SET!P8="","",SET!X8) | J10: =IF(SET!P8="","",SET!Y8) | K10: =IF(SET!P8="","",SUBSTITUTE(SET!AA8,"(Stream)","")) | L10: =IF(SET!P8="","",SUBSTITUTE(SET!AC8,"(Stream)","")) | M10: =IF(SET!P8="","",SET!T8) | N10: =IF(SET!P8="","",SET!S8) | O10: =IF(SET!P8="","",SET!U8)
A11: =IF(SET!P9="","",SET!L9) | B11: =IF(SET!P9="","",TEXT(DATE(SET!O9,SET!N9,SET!M9),"DD/MM/YYYY")) | C11: =IF(SET!P9="","",SET!P9) | D11: =IF(SET!P9="","",TEXT(TIME(SET!Q9,SET!R9,0),"HH:MM")) | E11: =IF(SET!P9="","",IF(SET!T9="iScout","📱",IF(SET!T9="XSA Neo","💻","📞"))) | F11: =IF(SET!P9="","",IFERROR(VLOOKUP(SET!U9,SET!$E$118:$G$161,2,FALSE),"⚽")) | G11: =IF(SET!P9="","",IFERROR(VLOOKUP(SET!V9,SET!$B$56:$C$270,2,FALSE),"🌍")) | H11: =IF(SET!P9="","",SET!W9) | I11: =IF(SET!P9="","",SET!X9) | J11: =IF(SET!P9="","",SET!Y9) | K11: =IF(SET!P9="","",SUBSTITUTE(SET!AA9,"(Stream)","")) | L11: =IF(SET!P9="","",SUBSTITUTE(SET!AC9,"(Stream)","")) | M11: =IF(SET!P9="","",SET!T9) | N11: =IF(SET!P9="","",SET!S9) | O11: =IF(SET!P9="","",SET!U9)
A12: =IF(SET!P10="","",SET!L10) | B12: =IF(SET!P10="","",TEXT(DATE(SET!O10,SET!N10,SET!M10),"DD/MM/YYYY")) | C12: =IF(SET!P10="","",SET!P10) | D12: =IF(SET!P10="","",TEXT(TIME(SET!Q10,SET!R10,0),"HH:MM")) | E12: =IF(SET!P10="","",IF(SET!T10="iScout","📱",IF(SET!T10="XSA Neo","💻","📞"))) | F12: =IF(SET!P10="","",IFERROR(VLOOKUP(SET!U10,SET!$E$118:$G$161,2,FALSE),"⚽")) | G12: =IF(SET!P10="","",IFERROR(VLOOKUP(SET!V10,SET!$B$56:$C$270,2,FALSE),"🌍")) | H12: =IF(SET!P10="","",SET!W10) | I12: =IF(SET!P10="","",SET!X10) | J12: =IF(SET!P10="","",SET!Y10) | K12: =IF(SET!P10="","",SUBSTITUTE(SET!AA10,"(Stream)","")) | L12: =IF(SET!P10="","",SUBSTITUTE(SET!AC10,"(Stream)","")) | M12: =IF(SET!P10="","",SET!T10) | N12: =IF(SET!P10="","",SET!S10) | O12: =IF(SET!P10="","",SET!U10)
A13: =IF(SET!P11="","",SET!L11) | B13: =IF(SET!P11="","",TEXT(DATE(SET!O11,SET!N11,SET!M11),"DD/MM/YYYY")) | C13: =IF(SET!P11="","",SET!P11) | D13: =IF(SET!P11="","",TEXT(TIME(SET!Q11,SET!R11,0),"HH:MM")) | E13: =IF(SET!P11="","",IF(SET!T11="iScout","📱",IF(SET!T11="XSA Neo","💻","📞"))) | F13: =IF(SET!P11="","",IFERROR(VLOOKUP(SET!U11,SET!$E$118:$G$161,2,FALSE),"⚽")) | G13: =IF(SET!P11="","",IFERROR(VLOOKUP(SET!V11,SET!$B$56:$C$270,2,FALSE),"🌍")) | H13: =IF(SET!P11="","",SET!W11) | I13: =IF(SET!P11="","",SET!X11) | J13: =IF(SET!P11="","",SET!Y11) | K13: =IF(SET!P11="","",SUBSTITUTE(SET!AA11,"(Stream)","")) | L13: =IF(SET!P11="","",SUBSTITUTE(SET!AC11,"(Stream)","")) | M13: =IF(SET!P11="","",SET!T11) | N13: =IF(SET!P11="","",SET!S11) | O13: =IF(SET!P11="","",SET!U11)
A14: =IF(SET!P12="","",SET!L12) | B14: =IF(SET!P12="","",TEXT(DATE(SET!O12,SET!N12,SET!M12),"DD/MM/YYYY")) | C14: =IF(SET!P12="","",SET!P12) | D14: =IF(SET!P12="","",TEXT(TIME(SET!Q12,SET!R12,0),"HH:MM")) | E14: =IF(SET!P12="","",IF(SET!T12="iScout","📱",IF(SET!T12="XSA Neo","💻","📞"))) | F14: =IF(SET!P12="","",IFERROR(VLOOKUP(SET!U12,SET!$E$118:$G$161,2,FALSE),"⚽")) | G14: =IF(SET!P12="","",IFERROR(VLOOKUP(SET!V12,SET!$B$56:$C$270,2,FALSE),"🌍")) | H14: =IF(SET!P12="","",SET!W12) | I14: =IF(SET!P12="","",SET!X12) | J14: =IF(SET!P12="","",SET!Y12) | K14: =IF(SET!P12="","",SUBSTITUTE(SET!AA12,"(Stream)","")) | L14: =IF(SET!P12="","",SUBSTITUTE(SET!AC12,"(Stream)","")) | M14: =IF(SET!P12="","",SET!T12) | N14: =IF(SET!P12="","",SET!S12) | O14: =IF(SET!P12="","",SET!U12)
... A81: =IF(SET!P79="","",SET!L79) | B81: =IF(SET!P79="","",TEXT(DATE(SET!O79,SET!N79,SET!M79),"DD/MM/YYYY")) | C81: =IF(SET!P79="","",SET!P79) | D81: =IF(SET!P79="","",TEXT(TIME(SET!Q79,SET!R79,0),"HH:MM")) | E81: =IF(SET!P79="","",IF(SET!T79="iScout","📱",IF(SET!T79="XSA Neo","💻","📞"))) | F81: =IF(SET!P79="","",IFERROR(VLOOKUP(SET!U79,SET!$E$118:$G$161,2,FALSE),"⚽")) | G81: =IF(SET!P79="","",IFERROR(VLOOKUP(SET!V79,SET!$B$56:$C$270,2,FALSE),"🌍")) | H81: =IF(SET!P79="","",SET!W79) | I81: =IF(SET!P79="","",SET!X79) | J81: =IF(SET!P79="","",SET!Y79) | K81: =IF(SET!P79="","",SUBSTITUTE(SET!AA79,"(Stream)","")) | L81: =IF(SET!P79="","",SUBSTITUTE(SET!AC79,"(Stream)","")) | M81: =IF(SET!P79="","",SET!T79) | N81: =IF(SET!P79="","",SET!S79) | O81: =IF(SET!P79="","",SET!U79)
A82: =IF(SET!P80="","",SET!L80) | B82: =IF(SET!P80="","",TEXT(DATE(SET!O80,SET!N80,SET!M80),"DD/MM/YYYY")) | D82: =IF(SET!P80="","",TEXT(TIME(SET!Q80,SET!R80,0),"HH:MM")) | E82: =IF(SET!P80="","",IF(SET!T80="iScout","📱",IF(SET!T80="XSA Neo","💻","📞"))) | F82: =IF(SET!P80="","",IFERROR(VLOOKUP(SET!U80,SET!$E$118:$G$161,2,FALSE),"⚽")) | G82: =IF(SET!P80="","",IFERROR(VLOOKUP(SET!V80,SET!$B$56:$C$270,2,FALSE),"🌍")) | H82: =IF(SET!P80="","",SET!W80) | I82: =IF(SET!P80="","",SET!X80) | J82: =IF(SET!P80="","",SET!Y80) | K82: =IF(SET!P80="","",SUBSTITUTE(SET!AA80,"(Stream)","")) | L82: =IF(SET!P80="","",SUBSTITUTE(SET!AC80,"(Stream)","")) | M82: =IF(SET!P80="","",SET!T80) | N82: =IF(SET!P80="","",SET!S80) | O82: =IF(SET!P80="","",SET!U80)
A83: =IF(SET!P81="","",SET!L81) | B83: =IF(SET!P81="","",TEXT(DATE(SET!O81,SET!N81,SET!M81),"DD/MM/YYYY")) | D83: =IF(SET!P81="","",TEXT(TIME(SET!Q81,SET!R81,0),"HH:MM")) | E83: =IF(SET!P81="","",IF(SET!T81="iScout","📱",IF(SET!T81="XSA Neo","💻","📞"))) | F83: =IF(SET!P81="","",IFERROR(VLOOKUP(SET!U81,SET!$E$118:$G$161,2,FALSE),"⚽")) | G83: =IF(SET!P81="","",IFERROR(VLOOKUP(SET!V81,SET!$B$56:$C$270,2,FALSE),"🌍")) | H83: =IF(SET!P81="","",SET!W81) | I83: =IF(SET!P81="","",SET!X81) | J83: =IF(SET!P81="","",SET!Y81) | K83: =IF(SET!P81="","",SUBSTITUTE(SET!AA81,"(Stream)","")) | L83: =IF(SET!P81="","",SUBSTITUTE(SET!AC81,"(Stream)","")) | M83: =IF(SET!P81="","",SET!T81) | N83: =IF(SET!P81="","",SET!S81) | O83: =IF(SET!P81="","",SET!U81)
A84: =IF(SET!P82="","",SET!L82) | E84: =IF(SET!A135="","",IF(SET!I135="iScout","📱",IF(SET!I135="XSA Neo","💻","📡")))
A85: =IF(SET!P83="","",SET!L83) | E85: =IF(SET!A136="","",IF(SET!I136="iScout","📱",IF(SET!I136="XSA Neo","💻","📡")))
A86: =IF(SET!P84="","",SET!L84) | E86: =IF(SET!A137="","",IF(SET!I137="iScout","📱",IF(SET!I137="XSA Neo","💻","📡")))
A87: =IF(SET!P85="","",SET!L85) | E87: =IF(SET!A138="","",IF(SET!I138="iScout","📱",IF(SET!I138="XSA Neo","💻","📡")))
A88: =IF(SET!P86="","",SET!L86) | E88: =IF(SET!A139="","",IF(SET!I139="iScout","📱",IF(SET!I139="XSA Neo","💻","📡")))
A89: =IF(SET!P87="","",SET!L87) | E89: =IF(SET!A140="","",IF(SET!I140="iScout","📱",IF(SET!I140="XSA Neo","💻","📡")))
A90: =IF(SET!P88="","",SET!L88) | E90: =IF(SET!A141="","",IF(SET!I141="iScout","📱",IF(SET!I141="XSA Neo","💻","📡")))
A91: =IF(SET!P89="","",SET!L89) | E91: =IF(SET!A142="","",IF(SET!I142="iScout","📱",IF(SET!I142="XSA Neo","💻","📡")))
A92: =IF(SET!P90="","",SET!L90) | E92: =IF(SET!A143="","",IF(SET!I143="iScout","📱",IF(SET!I143="XSA Neo","💻","📡")))
A93: =IF(SET!P91="","",SET!L91) | E93: =IF(SET!A144="","",IF(SET!I144="iScout","📱",IF(SET!I144="XSA Neo","💻","📡")))
A94: =IF(SET!P92="","",SET!L92) | E94: =IF(SET!A145="","",IF(SET!I145="iScout","📱",IF(SET!I145="XSA Neo","💻","📡")))
A95: =IF(SET!P93="","",SET!L93) | E95: =IF(SET!A146="","",IF(SET!I146="iScout","📱",IF(SET!I146="XSA Neo","💻","📡")))
... A108: =IF(SET!P106="","",SET!L106) | E108: =IF(SET!A159="","",IF(SET!I159="iScout","📱",IF(SET!I159="XSA Neo","💻","📡")))
E109: =IF(SET!A160="","",IF(SET!I160="iScout","📱",IF(SET!I160="XSA Neo","💻","📡")))
E110: =IF(SET!A161="","",IF(SET!I161="iScout","📱",IF(SET!I161="XSA Neo","💻","📡")))
E111: =IF(SET!A162="","",IF(SET!I162="iScout","📱",IF(SET!I162="XSA Neo","💻","📡")))
E112: =IF(SET!A163="","",IF(SET!I163="iScout","📱",IF(SET!I163="XSA Neo","💻","📡")))
E113: =IF(SET!A164="","",IF(SET!I164="iScout","📱",IF(SET!I164="XSA Neo","💻","📡")))
E114: =IF(SET!A165="","",IF(SET!I165="iScout","📱",IF(SET!I165="XSA Neo","💻","📡")))
E115: =IF(SET!A166="","",IF(SET!I166="iScout","📱",IF(SET!I166="XSA Neo","💻","📡")))
E116: =IF(SET!A167="","",IF(SET!I167="iScout","📱",IF(SET!I167="XSA Neo","💻","📡")))
E117: =IF(SET!A168="","",IF(SET!I168="iScout","📱",IF(SET!I168="XSA Neo","💻","📡")))
E118: =IF(SET!A169="","",IF(SET!I169="iScout","📱",IF(SET!I169="XSA Neo","💻","📡")))
...

Sheet DASH
A1: DASHBOARD
A2: 46054
A3: 0 | C3: 0 | E3: 0/0 | G3: -- | I3: -- | J3: 0 | K3: 0 | L3: 0 | M3: -- | N3: --
A4: Total Earnings | C4: Work Units | E4: Assigned / Covered | G4: Avg. Session | I4: Total Velocity | J4: Monthly Projections | K4: Streak | L4: Work Load | M4: Wasted Time | N4: Overall efficiency
A5: THIS WEEK | E5: DAY | F5: HOUR | G5: INFO | H5: STREAM | I5: HOME VS AWAY | K5: COMPARISONS
A6: MON | B6: □□□□□□□□□□□□□□□□□□□□□□□□ | D6: 0.0h | K6: Metric | L6: Δ | M6: Δ | N6: Δ
A7: TUE | B7: □□□□□□□□□□□□□□□□□□□□□□□□ | D7: 0.0h | K7: Earnings | L7: -- | M7: -- | N7: --
A8: WED | B8: □□□□□□□□□□□□□□□□□□□□□□□□ | D8: 0.0h | K8: Units | L8: -- | M8: -- | N8: --
A9: THU | B9: □□□□□□□□□□□□□□□□□□□□□□□□ | D9: 0.0h | K9: Wasted Time | L9: -- | M9: -- | N9: --
A10: FRI | B10: □□□□□□□□□□□□□□□□□□□□□□□□ | D10: 0.0h | K10: Best Day | L10: --
A11: SAT | B11: □□□□□□□□□□□□□□□□□□□□□□□□ | D11: 0.0h | K11: Total Sess | L11: --
A12: SUN | B12: □□□□□□□□□□□□□□□□□□□□□□□□ | D12: 0.0h | K12: Longest | L12: --
A13: SPORTS BREAKDOWN | K13: SESSION
A14: Soccer | B14: □□□□□□□□□□□□□□□□□□□□ | D14: 0 | K14: Duration | L14: --
A15: Basketball | B15: □□□□□□□□□□□□□□□□□□□□ | D15: 0 | L15: --
A16: Ice Hockey | B16: □□□□□□□□□□□□□□□□□□□□ | D16: 0 | K16: Games | L16: --
A17: E-Sport | B17: □□□□□□□□□□□□□□□□□□□□ | D17: 0 | K17: Status | L17: --
A18: Tennis | B18: □□□□□□□□□□□□□□□□□□□□ | D18: 0 | K18: MOST COVERED COUNTRIES
A19: Badminton | B19: □□□□□□□□□□□□□□□□□□□□ | D19: 0
A20: Rugby | B20: □□□□□□□□□□□□□□□□□□□□ | D20: 0
A21: Volleyball | B21: □□□□□□□□□□□□□□□□□□□□ | D21: 0
A22: Handball | B22: □□□□□□□□□□□□□□□□□□□□ | D22: 0
A23: Football | B23: □□□□□□□□□□□□□□□□□□□□ | D23: 0
A24: Other | B24: □□□□□□□□□□□□□□□□□□□□ | D24: 0

Sheet HIST
A1: ID | B1: DATE | C1: DAY | D1: TIME | E1: PLT | F1: SPORT | G1: CTRY | H1: TOURNAMENT | I1: HOME | J1: AWAY | K1: PRICE | L1: STATUS | M1: _SportName | N1: _Source
K2: =IF(M2="","",IFERROR(VLOOKUP(M2,SET!$A$2:$J$45,SET!$B$50+2,FALSE),""))
K3: =IF(M3="","",IFERROR(VLOOKUP(M3,SET!$A$2:$J$45,SET!$B$50+2,FALSE),""))
K4: =IF(M4="","",IFERROR(VLOOKUP(M4,SET!$A$2:$J$45,SET!$B$50+2,FALSE),""))
K5: =IF(M5="","",IFERROR(VLOOKUP(M5,SET!$A$2:$J$45,SET!$B$50+2,FALSE),""))
K6: =IF(M6="","",IFERROR(VLOOKUP(M6,SET!$A$2:$J$45,SET!$B$50+2,FALSE),""))
K7: =IF(M7="","",IFERROR(VLOOKUP(M7,SET!$A$2:$J$45,SET!$B$50+2,FALSE),""))
K8: =IF(M8="","",IFERROR(VLOOKUP(M8,SET!$A$2:$J$45,SET!$B$50+2,FALSE),""))
K9: =IF(M9="","",IFERROR(VLOOKUP(M9,SET!$A$2:$J$45,SET!$B$50+2,FALSE),""))
K10: =IF(M10="","",IFERROR(VLOOKUP(M10,SET!$A$2:$J$45,SET!$B$50+2,FALSE),""))
K11: =IF(M11="","",IFERROR(VLOOKUP(M11,SET!$A$2:$J$45,SET!$B$50+2,FALSE),""))
K12: =IF(M12="","",IFERROR(VLOOKUP(M12,SET!$A$2:$J$45,SET!$B$50+2,FALSE),""))
K13: =IF(M13="","",IFERROR(VLOOKUP(M13,SET!$A$2:$J$45,SET!$B$50+2,FALSE),""))
... K296: =IF(M296="","",IFERROR(VLOOKUP(M296,SET!$A$2:$J$45,SET!$B$50+2,FALSE),""))

Sheet SET
A1: =IFERROR(__xludf.DUMMYFUNCTION("ARRAYFORMULA(REGEXREPLACE(IMPORTRANGE(SET!B52,""Fees!A2:A46""),"" \(CAT \d+\)"",""""))"),"#REF!") -> #REF! | B1: =IFERROR(__xludf.DUMMYFUNCTION("IMPORTRANGE(SET!B52,""Fees!B2:J46"")"),"#REF!") -> #REF! | L1: =IFERROR(__xludf.DUMMYFUNCTION("QUERY( FILTER( IMPORTRANGE( ""1D-0aNDuuH_Td5DsoWXy9QPdmrgjYy9ZH4OyzK3P8BEc"", ""Scout Game v6!A2:S4000"" ), IMPORTRANGE( ""1D-0aNDuuH_Td5DsoWXy9QPdmrgjYy9ZH4OyzK3P8BEc"", ""Scout Game v6!O2:O4000"" ) = B49 ), "&"""SELECT Col1,Col2,Col3,Col4,Col5,Col6,Col7,Col8,Col9,Col10,Col11,Col12,Col13,Col14,Col15,Col16,Col17,Col18,Col19 ORDER BY Col4,Col3,Col2,Col6,Col7"", 0 ) "),"#REF!") -> #REF!
A48: SETTINGS | B48: VALUE
A49: MY NAME | B49: My Name
A50: CATEGORY | B50: 0
A51: Source Sheet ID | B51: Buraya Scout Game İdsi gelicek
A52: Pricing Sheet ID | B52: Buraya Freelancer Fees İdsi Gelicek
B56: Aruba | C56: 🇦🇼
B57: Bahamas | C57: 🇧🇸
B58: Barbados | C58: 🇧🇧
B59: Belize | C59: 🇧🇿
B60: Benin | C60: 🇧🇯
B61: Bermuda | C61: 🇧🇲
B62: Bhutan | C62: 🇧🇹
B63: Botswana | C63: 🇧🇼
B64: Brunei | C64: 🇧🇳
B65: Burkina Faso | C65: 🇧🇫
B66: Burundi | C66: 🇧🇮
B67: Cape Verde | C67: 🇨🇻
... B117: Réunion | C117: 🇷🇪
B118: International | C118: 🌍 | E118: SR Aussie Rules | F118: 🏈🦘 | G118: 2
B119: International Clubs | C119: 🌍 | E119: SR Badminton | F119: 🏸 | G119: 0.45
B120: Turkiye | C120: 🇹🇷 | E120: SR Baseball | F120: ⚾ | G120: 3.5
B121: Afghanistan | C121: 🇦🇫 | E121: SR Basketball | F121: 🏀 | G121: 2.1
B122: Albania | C122: 🇦🇱 | E122: SR Basketball Ex | F122: 🏀⏱️ | G122: 2.6
B123: Algeria | C123: 🇩🇿 | E123: SR Beach Volley | F123: 🏐🏖️ | G123: 1
B124: Argentina | C124: 🇦🇷 | E124: SR Cricket | F124: 🏏 | G124: 4
B125: Armenia | C125: 🇦🇲 | E125: SR Cricket Ex | F125: 🏏⏱️ | G125: 5
B126: Australia | C126: 🇦🇺 | E126: SR Cricket Long | F126: 🏏🌓 | G126: 6
B127: Austria | C127: 🇦🇹 | E127: SR Cricket Short | F127: 🏏⚡ | G127: 2
B128: Azerbaijan | C128: 🇦🇿 | E128: SR E-Sport Basketball | F128: 🎮🏀 | G128: 0.5
B129: Bahrain | C129: 🇧🇭 | E129: SR E-Sport Basketball Ex | F129: 🎮🏀⭐ | G129: 0.6
... B161: Greece | C161: 🇬🇷 | E161: RTS Water Polo | F161: 🤽 | G161: 2
B162: Guatemala | C162: 🇬🇹
B163: Honduras | C163: 🇭🇳
B164: Hong Kong | C164: 🇭🇰
B165: Hungary | C165: 🇭🇺
B166: Iceland | C166: 🇮🇸
B167: India | C167: 🇮🇳
B168: Indonesia | C168: 🇮🇩
B169: Iran | C169: 🇮🇷
...
